
---

# üìö **Nested Try-Catch with Throw and Throws in Java**

In Java, exceptions can be handled in a nested manner, where you have a `try-catch` block inside another `try-catch` block. This is useful when you need to handle different types of exceptions at different levels within the same method. Additionally, the `throw` and `throws` keywords can be combined with nested try-catch blocks to throw and declare exceptions.

## üõ†Ô∏è **What is Nested Try-Catch?**

A **nested try-catch** block occurs when a `try-catch` is placed inside another `try-catch` block. The outer `try-catch` can handle some exceptions, and the inner `try-catch` can handle more specific exceptions, allowing finer control over error handling.

---

## üìú **Syntax of Nested Try-Catch**

Here‚Äôs the basic structure of a nested `try-catch`:

```java
try {
    // Outer try block
    try {
        // Inner try block - specific code that might throw an exception
    } catch (SpecificException e1) {
        // Handle specific exception in inner try
    } catch (AnotherSpecificException e2) {
        // Handle another specific exception in inner try
    }
} catch (Exception e) {
    // Handle general exceptions from the outer try
}
```

The **outer `catch` block** handles exceptions that are thrown from both the outer and inner `try-catch` blocks.

---

## üéØ **Example of Nested Try-Catch with Throw and Throws**

### Scenario: 
We have a program that processes user input and performs division. The user may input a negative number or divide by zero, so we need to handle different exceptions at various levels.

### Code Example:

```java
class NestedTryCatchExample {
    public static void main(String[] args) {
        try {
            // Outer try block
            System.out.println("Outer try block started.");
            try {
                // Inner try block
                int result = divide(10, 0); // This will throw an ArithmeticException
                System.out.println("Result: " + result);
            } catch (ArithmeticException e) {
                System.out.println("Inner catch block: Error - " + e.getMessage());
                throw new ArithmeticException("Thrown from inner block"); // Throwing an exception
            } catch (IllegalArgumentException e) {
                System.out.println("Inner catch block: Illegal argument - " + e.getMessage());
            }
        } catch (Exception e) {
            // Outer catch block
            System.out.println("Outer catch block: " + e.getMessage());
        } finally {
            // Finally block to be executed after try-catch
            System.out.println("Finally block executed.");
        }
    }

    public static int divide(int a, int b) throws ArithmeticException, IllegalArgumentException {
        if (b == 0) {
            // Throwing an exception from the method
            throw new ArithmeticException("Cannot divide by zero");
        }
        if (a < 0 || b < 0) {
            // Throwing an exception for negative numbers
            throw new IllegalArgumentException("Input cannot be negative");
        }
        return a / b;
    }
}
```

### Explanation:

1. **Outer try block**: The outer block contains the call to the `divide()` method. It catches any exceptions that the inner block doesn't handle.
2. **Inner try block**: Inside the outer `try`, the `divide()` method is called. If any exception occurs in the method (e.g., division by zero), the inner `catch` block handles it.
3. **Inner catch block**: If an `ArithmeticException` occurs (like dividing by zero), it is caught in the inner `catch` block, and a new exception is thrown.
4. **Outer catch block**: The outer `catch` block is designed to catch any exception that is either thrown in the inner block or propagated upwards.
5. **`finally` block**: This block is executed regardless of whether an exception is thrown or not. It's useful for cleaning up resources like closing files, sockets, etc.

---

## üí° **Explanation of `throw` and `throws`**

- **`throw`**: The `throw` keyword is used to manually throw an exception from the code. In the example above, `throw` is used inside the inner `catch` block to throw a new exception when an `ArithmeticException` occurs.
- **`throws`**: The `throws` keyword is used in the method signature to declare that a method might throw an exception. In the `divide()` method, we use `throws` to declare that it might throw either an `ArithmeticException` or an `IllegalArgumentException`. This allows the caller (in this case, the outer `try-catch` block) to handle or propagate the exception further.

---

### **Output of the Example Code:**

```plaintext
Outer try block started.
Inner catch block: Error - Cannot divide by zero
Outer catch block: Thrown from inner block
Finally block executed.
```

---

## üßë‚Äçüíª **When to Use Nested Try-Catch?**

1. **Multiple Levels of Exception Handling**: When you need to handle different types of exceptions at different levels of your application. The outer block can catch broader exceptions, and the inner block can handle more specific exceptions.
2. **Resource Management**: Nested try-catch blocks can be useful when working with multiple resources or steps, allowing you to handle errors at each step and ensure proper cleanup.
3. **Custom Exception Handling**: Use nested try-catch to throw custom exceptions in the inner block and handle them in the outer block for more granular error control.

---

## ‚ö†Ô∏è **Key Points to Remember**

1. **Order of `catch` Blocks**: If you have multiple `catch` blocks, the order matters. The most specific exceptions should be caught first, followed by more general exceptions.
2. **Exception Propagation**: If an exception is thrown in the inner block, it can propagate to the outer block if not handled there. The outer block can then handle or rethrow the exception.
3. **Efficiency**: Avoid using nested try-catch blocks unless necessary. Too many nested blocks can make the code harder to read and maintain.

---

## üöÄ **Advanced Example: Using Nested `try-catch` with `throws`**

```java
class AdvancedExceptionHandling {

    public static void main(String[] args) {
        try {
            // Outer try block calling a method that throws exceptions
            processTransaction(0, -500);
        } catch (Exception e) {
            System.out.println("Caught Exception: " + e.getMessage());
        } finally {
            System.out.println("Transaction complete.");
        }
    }

    public static void processTransaction(int accountId, int amount) throws IllegalArgumentException, ArithmeticException {
        try {
            System.out.println("Processing transaction...");
            validateAccount(accountId);
            validateAmount(amount);
            int result = 100 / amount;  // This could throw ArithmeticException
        } catch (IllegalArgumentException e) {
            System.out.println("Account validation failed: " + e.getMessage());
            throw e;  // Re-throwing the exception
        } catch (ArithmeticException e) {
            System.out.println("Invalid amount for transaction: " + e.getMessage());
            throw e;  // Re-throwing the exception
        } finally {
            System.out.println("Transaction validation completed.");
        }
    }

    public static void validateAccount(int accountId) throws IllegalArgumentException {
        if (accountId <= 0) {
            throw new IllegalArgumentException("Account ID cannot be zero or negative.");
        }
    }

    public static void validateAmount(int amount) throws ArithmeticException {
        if (amount <= 0) {
            throw new ArithmeticException("Amount must be positive.");
        }
    }
}
```

### Explanation:

- The `processTransaction()` method is designed to validate account details and process a transaction.
- Exceptions are thrown and caught in the inner `try-catch` block and propagated back to the outer block.
- The `throws` keyword in the method signature ensures that the calling code knows this method may throw exceptions and must handle them.

---

## üéâ **Conclusion**

Using **nested try-catch** blocks along with `throw` and `throws` helps you structure your exception handling in a more flexible way. It allows you to catch exceptions at different levels of your application, rethrow exceptions if necessary, and handle errors in a way that makes your code cleaner and more maintainable.

Be sure to use nested try-catch blocks thoughtfully, as excessive nesting can make the code harder to maintain.